Workbook
Name GRADES: [1]Sheet1!$H$18:$I$25
Name GRADES2: [1]Sheet1!#REF!
Name GRADES2: [1]Sheet1!#REF!
Name Order_Month: [1]Orders!#REF!
Name Order_Month: [1]Orders!#REF!
Name Order_No: [1]Orders!$A$6:$A$1044
Name Order_Priority: [1]Orders!$J$6:$J$1044
Name Ship_Date: [1]Orders!$O$6:$O$1044
Name Ship_Time: [1]Orders!#REF!
Name Ship_Time: [1]Orders!#REF!
Name Slicer_Branch: #N/A
Name Slicer_Class: #N/A
Name Slicer_G._Segment: #N/A
Name Slicer_Years__Date: #N/A

Sheet Info
A1: Based on the given data Find
A4: 1 | B4: Use Data-1 Sheet, Change data to tabled data & Name it with your Name & Tack & Gov
A5: 2 | B5: ToTal sales
A6: 3 | B6: Total Profit
A7: 4 | B7: No of Quentity
A8: 5 | B8: Profit after Discount
A9: 6 | B9: Second High Sales
A10: 7 | B10: Fourth Low Sales
A11: 8 | B11: Max Profit
A12: 9 | B12: Total High Sales>3000
A13: 10 | B13: No of High Sales
A14: 11 | B14: IF New Price = 150 Find New Sales
A15: 12 | B15: Give Those classes to New Sales as Following
C16: A | D16: 2000 | E16: D | F16: 100
C17: B | D17: 1000 | E17: E | F17: less than 100
C18: C | D18: 500
A19: 13 | B19: Average of Top 3 Profit Value
A20: 14 | B20: Max new sales
A21: 15 | B21: Min new sales
A22: 16 | B22: average new sales
A23: 17 | B23: Find Total New sales If State = California
A24: 18 | B24: Find Average New Sales If state = Texas
A25: 19 | B25: Highlight All Sub Category = Phones ( using Custom Format)
A26: 20 | B26: Highlight all Negative Values in Profit
A27: 21 | B27: use code sheet to assign each code to relative data in Category Column
A28: 22 | B28: use spark line (Columns) to find change between sales & new sales
A29: 23 | B29: Based on Sales sheet, use Piviot Table to Find:
B30: ● | C30: Avgerage Profit by region
B31: ● | C31: sum of profit by region and segment
B32: ● | C32: Calculate discount by 5% on profit
B33: ● | C33: Count profit by category and sub category & segment
B34: ● | C34: insert slicer for each piviot
B35: ● | C35: insert piviot chart for all piviots and link them together
A36: 24 | B36: Use the data in sales sheet to analyze and convert all necessary data to chart from your own perspective
A37: 25 | B37: Create your Detailed interactive dashboard Based on analyzed data in NO (24)
A39: ** all answers in one book with the folowing Info:
A40: Delivery Period: | D40: 2 Days MAX
A41: Satuden Name: | D41: Areej fathy hassan gomaa
A42: Gov: | D42: power BI Tanta
A43: Group: | D43: 2
...

Sheet Data-1
N1: 150
A2: Row ID | B2: Ship Mode | C2: Segment | D2: State | E2: Region | F2: Category | G2: Category_Code | H2: Sub-Category | I2: Product Name | J2: Quantity | K2: Discount | L2: Profit | M2: profit after discount | N2: Sales | O2: New_Sales | P2: classes | Q2: sparkline
A3: 2 | B3: Second Class | C3: Consumer | D3: Kentucky | E3: South | F3: Furniture | G3: =VLOOKUP(Table1[[#This Row],[Category]],Code!$C$2:$D$5,2,0) -> F-101 | H3: Chairs | I3: Hon Deluxe Fabric Upholstered Stacking Chairs, Rounded Back | J3: 3 | K3: 0 | L3: 219.582 | M3: =Table1[[#This Row],[Sales]]*Table1[[#This Row],[Discount]] -> 0 | N3: 731.94 | O3: =Table1[[#This Row],[Quantity]]*$N$1 -> 450 | P3: {=_xlfn.IFS(Table1[[#This Row],[New_Sales]]>=2000,"A",Table1[[#This Row],[New_Sales]]>=1000,"B",Table1[[#This Row],[New_Sales]]>=500,"C",Table1[[#This Row],[New_Sales]]>=100,"D",Table1[[#This Row],[New_Sales]]<100,"E")} -> D
A4: 3 | B4: Second Class | C4: Corporate | D4: California | E4: West | F4: Office Supplies | G4: =VLOOKUP(Table1[[#This Row],[Category]],Code!$C$2:$D$5,2,0) -> O-102 | H4: Labels | I4: Self-Adhesive Address Labels for Typewriters by Universal | J4: 2 | K4: 0 | L4: 6.8714 | M4: =Table1[[#This Row],[Sales]]*Table1[[#This Row],[Discount]] -> 0 | O4: =Table1[[#This Row],[Quantity]]*$N$1 -> 300 | P4: {=_xlfn.IFS(Table1[[#This Row],[New_Sales]]>=2000,"A",Table1[[#This Row],[New_Sales]]>=1000,"B",Table1[[#This Row],[New_Sales]]>=500,"C",Table1[[#This Row],[New_Sales]]>=100,"D",Table1[[#This Row],[New_Sales]]<100,"E")} -> D
A5: 4 | B5: Standard Class | C5: Consumer | D5: Florida | E5: South | F5: Furniture | G5: =VLOOKUP(Table1[[#This Row],[Category]],Code!$C$2:$D$5,2,0) -> F-101 | H5: Tables | I5: Bretford CR4500 Series Slim Rectangular Table | J5: 5 | K5: 0.45 | L5: -383.031 | M5: =Table1[[#This Row],[Sales]]*Table1[[#This Row],[Discount]] -> 430.90987 | N5: 957.5775 | O5: =Table1[[#This Row],[Quantity]]*$N$1 -> 750 | P5: {=_xlfn.IFS(Table1[[#This Row],[New_Sales]]>=2000,"A",Table1[[#This Row],[New_Sales]]>=1000,"B",Table1[[#This Row],[New_Sales]]>=500,"C",Table1[[#This Row],[New_Sales]]>=100,"D",Table1[[#This Row],[New_Sales]]<100,"E")} -> C
A6: 5 | B6: Standard Class | C6: Consumer | D6: Florida | E6: South | F6: Office Supplies | G6: =VLOOKUP(Table1[[#This Row],[Category]],Code!$C$2:$D$5,2,0) -> O-102 | H6: Storage | I6: Eldon Fold 'N Roll Cart System | J6: 2 | K6: 0.2 | L6: 2.5164 | M6: =Table1[[#This Row],[Sales]]*Table1[[#This Row],[Discount]] -> 4.4736 | N6: 22.368 | O6: =Table1[[#This Row],[Quantity]]*$N$1 -> 300 | P6: {=_xlfn.IFS(Table1[[#This Row],[New_Sales]]>=2000,"A",Table1[[#This Row],[New_Sales]]>=1000,"B",Table1[[#This Row],[New_Sales]]>=500,"C",Table1[[#This Row],[New_Sales]]>=100,"D",Table1[[#This Row],[New_Sales]]<100,"E")} -> D
A7: 6 | B7: Standard Class | C7: Consumer | D7: California | E7: West | F7: Furniture | G7: =VLOOKUP(Table1[[#This Row],[Category]],Code!$C$2:$D$5,2,0) -> F-101 | H7: Furnishings | I7: Eldon Expressions Wood and Plastic Desk Accessories, Cherry Wood | J7: 7 | K7: 0 | L7: 14.1694 | M7: =Table1[[#This Row],[Sales]]*Table1[[#This Row],[Discount]] -> 0 | N7: 48.86 | O7: =Table1[[#This Row],[Quantity]]*$N$1 -> 1050 | P7: {=_xlfn.IFS(Table1[[#This Row],[New_Sales]]>=2000,"A",Table1[[#This Row],[New_Sales]]>=1000,"B",Table1[[#This Row],[New_Sales]]>=500,"C",Table1[[#This Row],[New_Sales]]>=100,"D",Table1[[#This Row],[New_Sales]]<100,"E")} -> B
A8: 7 | B8: Standard Class | C8: Consumer | D8: California | E8: West | F8: Office Supplies | G8: =VLOOKUP(Table1[[#This Row],[Category]],Code!$C$2:$D$5,2,0) -> O-102 | H8: Art | I8: Newell 322 | J8: 4 | K8: 0 | L8: 1.9656 | M8: =Table1[[#This Row],[Sales]]*Table1[[#This Row],[Discount]] -> 0 | N8: 7.28 | O8: =Table1[[#This Row],[Quantity]]*$N$1 -> 600 | P8: {=_xlfn.IFS(Table1[[#This Row],[New_Sales]]>=2000,"A",Table1[[#This Row],[New_Sales]]>=1000,"B",Table1[[#This Row],[New_Sales]]>=500,"C",Table1[[#This Row],[New_Sales]]>=100,"D",Table1[[#This Row],[New_Sales]]<100,"E")} -> C
A9: 8 | B9: Standard Class | C9: Consumer | D9: California | E9: West | F9: Technology | G9: =VLOOKUP(Table1[[#This Row],[Category]],Code!$C$2:$D$5,2,0) -> T-103 | H9: Phones | I9: Mitel 5320 IP Phone VoIP phone | J9: 6 | K9: 0.2 | L9: 90.7152 | M9: =Table1[[#This Row],[Sales]]*Table1[[#This Row],[Discount]] -> 181.4304 | N9: 907.152 | O9: =Table1[[#This Row],[Quantity]]*$N$1 -> 900 | P9: {=_xlfn.IFS(Table1[[#This Row],[New_Sales]]>=2000,"A",Table1[[#This Row],[New_Sales]]>=1000,"B",Table1[[#This Row],[New_Sales]]>=500,"C",Table1[[#This Row],[New_Sales]]>=100,"D",Table1[[#This Row],[New_Sales]]<100,"E")} -> C
A10: 9 | B10: Standard Class | C10: Consumer | D10: California | E10: West | F10: Office Supplies | G10: =VLOOKUP(Table1[[#This Row],[Category]],Code!$C$2:$D$5,2,0) -> O-102 | H10: Binders | I10: DXL Angle-View Binders with Locking Rings by Samsill | J10: 3 | K10: 0.2 | L10: 5.7825 | M10: =Table1[[#This Row],[Sales]]*Table1[[#This Row],[Discount]] -> 3.7008 | N10: 18.504 | O10: =Table1[[#This Row],[Quantity]]*$N$1 -> 450 | P10: {=_xlfn.IFS(Table1[[#This Row],[New_Sales]]>=2000,"A",Table1[[#This Row],[New_Sales]]>=1000,"B",Table1[[#This Row],[New_Sales]]>=500,"C",Table1[[#This Row],[New_Sales]]>=100,"D",Table1[[#This Row],[New_Sales]]<100,"E")} -> D
A11: 10 | B11: Standard Class | C11: Consumer | D11: California | E11: West | F11: Office Supplies | G11: =VLOOKUP(Table1[[#This Row],[Category]],Code!$C$2:$D$5,2,0) -> O-102 | H11: Appliances | I11: Belkin F5C206VTEL 6 Outlet Surge | J11: 5 | K11: 0 | L11: 34.47 | M11: =Table1[[#This Row],[Sales]]*Table1[[#This Row],[Discount]] -> 0 | N11: 114.9 | O11: =Table1[[#This Row],[Quantity]]*$N$1 -> 750 | P11: {=_xlfn.IFS(Table1[[#This Row],[New_Sales]]>=2000,"A",Table1[[#This Row],[New_Sales]]>=1000,"B",Table1[[#This Row],[New_Sales]]>=500,"C",Table1[[#This Row],[New_Sales]]>=100,"D",Table1[[#This Row],[New_Sales]]<100,"E")} -> C
A12: 11 | B12: Standard Class | C12: Consumer | D12: California | E12: West | F12: Furniture | G12: =VLOOKUP(Table1[[#This Row],[Category]],Code!$C$2:$D$5,2,0) -> F-101 | H12: Tables | I12: Chromcraft Rectangular Conference Tables | J12: 9 | K12: 0.2 | L12: 85.3092 | M12: =Table1[[#This Row],[Sales]]*Table1[[#This Row],[Discount]] -> 341.2368 | N12: 1706.184 | O12: =Table1[[#This Row],[Quantity]]*$N$1 -> 1350 | P12: {=_xlfn.IFS(Table1[[#This Row],[New_Sales]]>=2000,"A",Table1[[#This Row],[New_Sales]]>=1000,"B",Table1[[#This Row],[New_Sales]]>=500,"C",Table1[[#This Row],[New_Sales]]>=100,"D",Table1[[#This Row],[New_Sales]]<100,"E")} -> B
A13: 12 | B13: Standard Class | C13: Consumer | D13: California | E13: West | F13: Technology | G13: =VLOOKUP(Table1[[#This Row],[Category]],Code!$C$2:$D$5,2,0) -> T-103 | H13: Phones | I13: Konftel 250 Conference phone - Charcoal black | J13: 4 | K13: 0.2 | L13: 68.3568 | M13: =Table1[[#This Row],[Sales]]*Table1[[#This Row],[Discount]] -> 182.2848 | N13: 911.424 | O13: =Table1[[#This Row],[Quantity]]*$N$1 -> 600 | P13: {=_xlfn.IFS(Table1[[#This Row],[New_Sales]]>=2000,"A",Table1[[#This Row],[New_Sales]]>=1000,"B",Table1[[#This Row],[New_Sales]]>=500,"C",Table1[[#This Row],[New_Sales]]>=100,"D",Table1[[#This Row],[New_Sales]]<100,"E")} -> C
A14: 13 | B14: Standard Class | C14: Consumer | D14: North Carolina | E14: South | F14: Office Supplies | G14: =VLOOKUP(Table1[[#This Row],[Category]],Code!$C$2:$D$5,2,0) -> O-102 | H14: Paper | I14: Xerox 1967 | J14: 3 | K14: 0.2 | L14: 5.4432 | M14: =Table1[[#This Row],[Sales]]*Table1[[#This Row],[Discount]] -> 3.1104 | N14: 15.552 | O14: =Table1[[#This Row],[Quantity]]*$N$1 -> 450 | P14: {=_xlfn.IFS(Table1[[#This Row],[New_Sales]]>=2000,"A",Table1[[#This Row],[New_Sales]]>=1000,"B",Table1[[#This Row],[New_Sales]]>=500,"C",Table1[[#This Row],[New_Sales]]>=100,"D",Table1[[#This Row],[New_Sales]]<100,"E")} -> D
A15: 14 | B15: Standard Class | C15: Consumer | D15: Washington | E15: West | F15: Office Supplies | G15: =VLOOKUP(Table1[[#This Row],[Category]],Code!$C$2:$D$5,2,0) -> O-102 | H15: Binders | I15: Fellowes PB200 Plastic Comb Binding Machine | J15: 3 | K15: 0.2 | L15: 132.5922 | M15: =Table1[[#This Row],[Sales]]*Table1[[#This Row],[Discount]] -> 81.5952 | N15: 407.976 | O15: =Table1[[#This Row],[Quantity]]*$N$1 -> 450 | P15: {=_xlfn.IFS(Table1[[#This Row],[New_Sales]]>=2000,"A",Table1[[#This Row],[New_Sales]]>=1000,"B",Table1[[#This Row],[New_Sales]]>=500,"C",Table1[[#This Row],[New_Sales]]>=100,"D",Table1[[#This Row],[New_Sales]]<100,"E")} -> D
A16: 15 | B16: Standard Class | C16: Home Office | D16: Texas | E16: Central | F16: Office Supplies | G16: =VLOOKUP(Table1[[#This Row],[Category]],Code!$C$2:$D$5,2,0) -> O-102 | H16: Appliances | I16: Holmes Replacement Filter for HEPA Air Cleaner, Very Large Room, HEPA Filter | J16: 5 | K16: 0.8 | L16: -123.858 | M16: =Table1[[#This Row],[Sales]]*Table1[[#This Row],[Discount]] -> 55.048 | N16: 68.81 | O16: =Table1[[#This Row],[Quantity]]*$N$1 -> 750 | P16: {=_xlfn.IFS(Table1[[#This Row],[New_Sales]]>=2000,"A",Table1[[#This Row],[New_Sales]]>=1000,"B",Table1[[#This Row],[New_Sales]]>=500,"C",Table1[[#This Row],[New_Sales]]>=100,"D",Table1[[#This Row],[New_Sales]]<100,"E")} -> C
... A1999: 1998 | B1999: First Class | C1999: Corporate | D1999: Virginia | E1999: South | F1999: Office Supplies | G1999: =VLOOKUP(Table1[[#This Row],[Category]],Code!$C$2:$D$5,2,0) -> O-102 | H1999: Labels | I1999: Avery 480 | J1999: 4 | K1999: 0 | L1999: 7.2 | M1999: =Table1[[#This Row],[Sales]]*Table1[[#This Row],[Discount]] -> 0 | N1999: 15 | O1999: =Table1[[#This Row],[Quantity]]*$N$1 -> 600 | P1999: {=_xlfn.IFS(Table1[[#This Row],[New_Sales]]>=2000,"A",Table1[[#This Row],[New_Sales]]>=1000,"B",Table1[[#This Row],[New_Sales]]>=500,"C",Table1[[#This Row],[New_Sales]]>=100,"D",Table1[[#This Row],[New_Sales]]<100,"E")} -> C
A2000: 1999 | B2000: First Class | C2000: Corporate | D2000: Virginia | E2000: South | F2000: Technology | G2000: =VLOOKUP(Table1[[#This Row],[Category]],Code!$C$2:$D$5,2,0) -> T-103 | H2000: Phones | I2000: Aastra 57i VoIP phone | J2000: 1 | K2000: 0 | L2000: 42.0186 | M2000: =Table1[[#This Row],[Sales]]*Table1[[#This Row],[Discount]] -> 0 | N2000: 161.61 | O2000: =Table1[[#This Row],[Quantity]]*$N$1 -> 150 | P2000: {=_xlfn.IFS(Table1[[#This Row],[New_Sales]]>=2000,"A",Table1[[#This Row],[New_Sales]]>=1000,"B",Table1[[#This Row],[New_Sales]]>=500,"C",Table1[[#This Row],[New_Sales]]>=100,"D",#REF!<100,"E")} -> D
B2004: ToTal sales | C2004: =SUM(Table1[Sales]) -> 457476.53 | D2004: Average of Top 3 Profit Value | E2004: =AVERAGE(LARGE(Table1[Profit],1),LARGE(Table1[Profit],2),LARGE(Table1[Profit],3)) -> 2524.8102
B2005: Total Profit | C2005: =SUM(Table1[Profit]) -> 43166.234 | D2005: Max new sales | E2005: =MAX(Table1[New_Sales]) -> 2100
B2006: No of Quentity | C2006: =COUNT(Table1[Quantity]) -> 1998 | D2006: Min new sales | E2006: =MIN(Table1[New_Sales]) -> 150
B2007: Profit after Discount | C2007: done | D2007: average new sales | E2007: =AVERAGE(Table1[New_Sales]) -> 568.24324
B2008: Second High Sales | C2008: =LARGE(Table1[Sales],2) -> 7999.98 | D2008: Find Total New sales If State = California | E2008: =SUMIF(Table1[State],"=california",Table1[New_Sales]) -> 213300
B2009: Fourth Low Sales | C2009: =SMALL(Table1[Sales],4) -> 1.188 | D2009: Find Average New Sales If state = Texas | E2009: =AVERAGEIF(Table1[State],"=texas",Table1[Sales]) -> 253.93705
B2010: Max Profit | C2010: =MAX(Table1[Profit]) -> 3177.475
B2011: Total High Sales>3000 | C2011: =SUMIF(Table1[Sales],">3000",Table1[Sales]) -> 62777.238
B2012: No of High Sales | C2012: =COUNTIF(Table1[Sales],">3000") -> 14

Sheet Code
C2: Category | D2: Code
C3: Furniture | D3: F-101
C4: Office Supplies | D4: O-102
C5: Technology | D5: T-103

Sheet Sales
A1: Date | B1: Branch | C1: G. Segment | D1: Product | E1: Class | F1: Quantity | G1: Unit Cost | H1: Unit Price | I1: COGS | J1: Sales
A2: 40909 | B2: Marasa Matrouh | C2: Alexandria | D2: Nokia Lumia - 4G | E2: Smartphones | F2: 8 | G2: 2034 | H2: 2160 | I2: 16272 | J2: 40053
A3: 40909 | B3: Alex | C3: Alexandria | D3: Samsung Galaxy Note 10.1 | E3: Tablets | F3: 21 | G3: 3582 | H3: 3870 | I3: 75222 | J3: 81270
A4: 40909 | B4: Zagazig | C4: Delta | D4: Samsung Galaxy Note3 (32GB) - 4G | E4: Smartphones | F4: 16 | G4: 3978 | H4: 4230 | I4: 63648 | J4: 67680
A5: 40909 | B5: Mansoura | C5: Delta | D5: Samsung Galaxy S3 (16GB) - 3G | E5: Smartphones | F5: 23 | G5: 2196 | H5: 2340 | I5: 50508 | J5: 53820
A6: 40910 | B6: Ismailia | C6: Canal | D6: Samsung Galaxy Note3 (32GB) - 4G | E6: Smartphones | F6: 22 | G6: 3978 | H6: 4230 | I6: 87516 | J6: 93060
A7: 40910 | B7: Minia | C7: Upper Egypt | D7: Samsung Galaxy Note3 (32GB) - 4G | E7: Smartphones | F7: 13 | G7: 3978 | H7: 4230 | I7: 51714 | J7: 54990
A8: 40910 | B8: Alex | C8: Alexandria | D8: Samsung Galaxy S4 (16GB) - 4G | E8: Smartphones | F8: 27 | G8: 3042 | H8: 3240 | I8: 82134 | J8: 87480
A9: 40910 | B9: Portsaied | C9: Canal | D9: Samsung Galaxy Note3 (32GB) - 4G | E9: Smartphones | F9: 27 | G9: 3978 | H9: 4230 | I9: 107406 | J9: 114210
A10: 40912 | B10: Marasa Matrouh | C10: Alexandria | D10: Samsung Galaxy Note3 (32GB) - 4G | E10: Smartphones | F10: 27 | G10: 3978 | H10: 4230 | I10: 107406 | J10: 114210
A11: 40913 | B11: Minia | C11: Upper Egypt | D11: iPhone 5S (64GB) | E11: Smartphones | F11: 27 | G11: 5832 | H11: 6210 | I11: 157464 | J11: 167670
A12: 40913 | B12: Cairo | C12: G. Cairo | D12: Samsung Galaxy S3 (16GB) - 3G | E12: Smartphones | F12: 27 | G12: 2196 | H12: 2340 | I12: 59292 | J12: 63180
A13: 40913 | B13: Giza | C13: G. Cairo | D13: iPhone 5C (16GB) | E13: Smartphones | F13: 27 | G13: 3546 | H13: 3780 | I13: 95742 | J13: 102060
... A3001: 41912 | B3001: Portsaied | C3001: Canal | D3001: iPhone 5C (32GB) | E3001: Smartphones | F3001: 6 | G3001: 3546 | H3001: 3780 | I3001: 3978 | J3001: 4230

Sheet Sales table
A1: Date | B1: Branch | C1: G. Segment | D1: Product | E1: Class | F1: Quantity | G1: Unit Cost | H1: Unit Price | I1: COGS | J1: Sales | K1: Profit | L1: Profit after discount | M1: sales after discount | N1: profit margin
A2: 40909 | B2: Marasa Matrouh | C2: Alexandria | D2: Nokia Lumia - 4G | E2: Smartphones | F2: 8 | G2: 2034 | H2: 2160 | I2: 16272 | J2: 40053 | K2: =sales_table[[#This Row],[Sales]]-sales_table[[#This Row],[COGS]] -> 23781 | L2: =sales_table[[#This Row],[sales after discount]]-sales_table[[#This Row],[COGS]] -> 21778.35 | M2: =sales_table[[#This Row],[Sales]]*0.95 -> 38050.35 | N2: =(sales_table[[#This Row],[Profit]]/sales_table[[#This Row],[Sales]]) -> 0.5937383
A3: 40909 | B3: Alex | C3: Alexandria | D3: Samsung Galaxy Note 10.1 | E3: Tablets | F3: 21 | G3: 3582 | H3: 3870 | I3: 75222 | J3: 81270 | K3: =sales_table[[#This Row],[Sales]]-sales_table[[#This Row],[COGS]] -> 6048 | L3: =sales_table[[#This Row],[sales after discount]]-sales_table[[#This Row],[COGS]] -> 1984.5 | M3: =sales_table[[#This Row],[Sales]]*0.95 -> 77206.5 | N3: =(sales_table[[#This Row],[Profit]]/sales_table[[#This Row],[Sales]]) -> 0.074418605
A4: 40909 | B4: Zagazig | C4: Delta | D4: Samsung Galaxy Note3 (32GB) - 4G | E4: Smartphones | F4: 16 | G4: 3978 | H4: 4230 | I4: 63648 | J4: 67680 | K4: =sales_table[[#This Row],[Sales]]-sales_table[[#This Row],[COGS]] -> 4032 | L4: =sales_table[[#This Row],[sales after discount]]-sales_table[[#This Row],[COGS]] -> 648 | M4: =sales_table[[#This Row],[Sales]]*0.95 -> 64296 | N4: =(sales_table[[#This Row],[Profit]]/sales_table[[#This Row],[Sales]]) -> 0.059574468
A5: 40909 | B5: Mansoura | C5: Delta | D5: Samsung Galaxy S3 (16GB) - 3G | E5: Smartphones | F5: 23 | G5: 2196 | H5: 2340 | I5: 50508 | J5: 53820 | K5: =sales_table[[#This Row],[Sales]]-sales_table[[#This Row],[COGS]] -> 3312 | L5: =sales_table[[#This Row],[sales after discount]]-sales_table[[#This Row],[COGS]] -> 621 | M5: =sales_table[[#This Row],[Sales]]*0.95 -> 51129 | N5: =(sales_table[[#This Row],[Profit]]/sales_table[[#This Row],[Sales]]) -> 0.061538462
A6: 40910 | B6: Ismailia | C6: Canal | D6: Samsung Galaxy Note3 (32GB) - 4G | E6: Smartphones | F6: 22 | G6: 3978 | H6: 4230 | I6: 87516 | J6: 93060 | K6: =sales_table[[#This Row],[Sales]]-sales_table[[#This Row],[COGS]] -> 5544 | L6: =sales_table[[#This Row],[sales after discount]]-sales_table[[#This Row],[COGS]] -> 891 | M6: =sales_table[[#This Row],[Sales]]*0.95 -> 88407 | N6: =(sales_table[[#This Row],[Profit]]/sales_table[[#This Row],[Sales]]) -> 0.059574468
A7: 40910 | B7: Minia | C7: Upper Egypt | D7: Samsung Galaxy Note3 (32GB) - 4G | E7: Smartphones | F7: 13 | G7: 3978 | H7: 4230 | I7: 51714 | J7: 54990 | K7: =sales_table[[#This Row],[Sales]]-sales_table[[#This Row],[COGS]] -> 3276 | L7: =sales_table[[#This Row],[sales after discount]]-sales_table[[#This Row],[COGS]] -> 526.5 | M7: =sales_table[[#This Row],[Sales]]*0.95 -> 52240.5 | N7: =(sales_table[[#This Row],[Profit]]/sales_table[[#This Row],[Sales]]) -> 0.059574468
A8: 40910 | B8: Alex | C8: Alexandria | D8: Samsung Galaxy S4 (16GB) - 4G | E8: Smartphones | F8: 27 | G8: 3042 | H8: 3240 | I8: 82134 | J8: 87480 | K8: =sales_table[[#This Row],[Sales]]-sales_table[[#This Row],[COGS]] -> 5346 | L8: =sales_table[[#This Row],[sales after discount]]-sales_table[[#This Row],[COGS]] -> 972 | M8: =sales_table[[#This Row],[Sales]]*0.95 -> 83106 | N8: =(sales_table[[#This Row],[Profit]]/sales_table[[#This Row],[Sales]]) -> 0.061111111
A9: 40910 | B9: Portsaied | C9: Canal | D9: Samsung Galaxy Note3 (32GB) - 4G | E9: Smartphones | F9: 27 | G9: 3978 | H9: 4230 | I9: 107406 | J9: 114210 | K9: =sales_table[[#This Row],[Sales]]-sales_table[[#This Row],[COGS]] -> 6804 | L9: =sales_table[[#This Row],[sales after discount]]-sales_table[[#This Row],[COGS]] -> 1093.5 | M9: =sales_table[[#This Row],[Sales]]*0.95 -> 108499.5 | N9: =(sales_table[[#This Row],[Profit]]/sales_table[[#This Row],[Sales]]) -> 0.059574468
A10: 40912 | B10: Marasa Matrouh | C10: Alexandria | D10: Samsung Galaxy Note3 (32GB) - 4G | E10: Smartphones | F10: 27 | G10: 3978 | H10: 4230 | I10: 107406 | J10: 114210 | K10: =sales_table[[#This Row],[Sales]]-sales_table[[#This Row],[COGS]] -> 6804 | L10: =sales_table[[#This Row],[sales after discount]]-sales_table[[#This Row],[COGS]] -> 1093.5 | M10: =sales_table[[#This Row],[Sales]]*0.95 -> 108499.5 | N10: =(sales_table[[#This Row],[Profit]]/sales_table[[#This Row],[Sales]]) -> 0.059574468
A11: 40913 | B11: Minia | C11: Upper Egypt | D11: iPhone 5S (64GB) | E11: Smartphones | F11: 27 | G11: 5832 | H11: 6210 | I11: 157464 | J11: 167670 | K11: =sales_table[[#This Row],[Sales]]-sales_table[[#This Row],[COGS]] -> 10206 | L11: =sales_table[[#This Row],[sales after discount]]-sales_table[[#This Row],[COGS]] -> 1822.5 | M11: =sales_table[[#This Row],[Sales]]*0.95 -> 159286.5 | N11: =(sales_table[[#This Row],[Profit]]/sales_table[[#This Row],[Sales]]) -> 0.060869565
A12: 40913 | B12: Cairo | C12: G. Cairo | D12: Samsung Galaxy S3 (16GB) - 3G | E12: Smartphones | F12: 27 | G12: 2196 | H12: 2340 | I12: 59292 | J12: 63180 | K12: =sales_table[[#This Row],[Sales]]-sales_table[[#This Row],[COGS]] -> 3888 | L12: =sales_table[[#This Row],[sales after discount]]-sales_table[[#This Row],[COGS]] -> 729 | M12: =sales_table[[#This Row],[Sales]]*0.95 -> 60021 | N12: =(sales_table[[#This Row],[Profit]]/sales_table[[#This Row],[Sales]]) -> 0.061538462
A13: 40913 | B13: Giza | C13: G. Cairo | D13: iPhone 5C (16GB) | E13: Smartphones | F13: 27 | G13: 3546 | H13: 3780 | I13: 95742 | J13: 102060 | K13: =sales_table[[#This Row],[Sales]]-sales_table[[#This Row],[COGS]] -> 6318 | L13: =sales_table[[#This Row],[sales after discount]]-sales_table[[#This Row],[COGS]] -> 1215 | M13: =sales_table[[#This Row],[Sales]]*0.95 -> 96957 | N13: =(sales_table[[#This Row],[Profit]]/sales_table[[#This Row],[Sales]]) -> 0.061904762
... A3001: 41912 | B3001: Portsaied | C3001: Canal | D3001: iPhone 5C (32GB) | E3001: Smartphones | F3001: 6 | G3001: 3546 | H3001: 3780 | I3001: 3978 | J3001: 4230 | K3001: =sales_table[[#This Row],[Sales]]-sales_table[[#This Row],[COGS]] -> 252 | L3001: =sales_table[[#This Row],[sales after discount]]-sales_table[[#This Row],[COGS]] -> 40.5 | M3001: =sales_table[[#This Row],[Sales]]*0.95 -> 4018.5 | N3001: =(sales_table[[#This Row],[Profit]]/sales_table[[#This Row],[Sales]]) -> 0.059574468

Sheet PVT
A3: Region | B3: Average of Profit | D3: Region | E3: Sum of Profit | G3: Region | H3: Sum of Profit after discount | L3: Region | M3: Sum of Sales | N3: Sum of Profit
A4: Alexandria | B4: 3473.5857 | D4: Upper Egypt | E4: 1915218 | G4: Alexandria | H4: 467975.85 | L4: Alex | M4: 15606990 | N4: 997830
A5: Canal | B5: 3565.3048 | D5: G. Cairo | E5: 2023722 | G5: Alex | H5: 217480.5 | L5: Aswan | M5: 15088500 | N5: 965772
A6: Delta | B6: 3388.3888 | D6: Delta | E6: 2056752 | G6: Marasa Matrouh | H6: 250495.35 | L6: Cairo | M6: 15751710 | N6: 1008450
A7: G. Cairo | B7: 3389.8191 | D7: Alexandria | E7: 2087625 | G7: Canal | H7: 466069.5 | L7: Giza | M7: 15953760 | N7: 1015272
A8: Upper Egypt | B8: 3257.1735 | D8: Canal | E8: 2164140 | G8: Ismailia | H8: 217147.5 | L8: Ismailia | M8: 16228530 | N8: 1028574
A9: Grand Total | B9: 3415.819 | D9: Grand Total | E9: 10247457 | G9: Portsaied | H9: 248922 | L9: Mansoura | M9: 15999210 | N9: 1035432
G10: Delta | H10: 458136 | L10: Marasa Matrouh | M10: 16785993 | N10: 1089795
G11: Mansoura | H11: 235471.5 | L11: Minia | M11: 14953230 | N11: 949446
G12: Zagazig | H12: 222664.5 | L12: Portsaied | M12: 17732880 | N12: 1135566
A13: Sum of Profit | B13: Sum of Quantity | C13: Sum of Sales | G13: G. Cairo | H13: 438448.5 | L13: Zagazig | M13: 15973110 | N13: 1021320
A14: 10247457 | B14: 43608 | C14: 160073913 | G14: Cairo | H14: 220864.5 | L14: Grand Total | M14: 160073913 | N14: 10247457
G15: Giza | H15: 217584
A16: =GETPIVOTDATA("Sum of Profit",$A$13)/GETPIVOTDATA("Sum of Sales",$A$13) -> 0.064017033 | G16: Upper Egypt | H16: 413131.5
G17: Aswan | H17: 211347
G18: Minia | H18: 201784.5
G19: Grand Total | H19: 2243761.4
A21: Sum of Profit | B21: G.Segment
A22: Class&Product | B22: Alexandria | C22: Canal | D22: Delta | E22: G. Cairo | F22: Upper Egypt | G22: Grand Total
A23: Smartphones | B23: 1527357 | C23: 1588698 | D23: 1408104 | E23: 1492794 | F23: 1401228 | G23: 7418181
A24: Tablets | B24: 560268 | C24: 575442 | D24: 648648 | E24: 530928 | F24: 513990 | G24: 2829276
A25: Grand Total | B25: 2087625 | C25: 2164140 | D25: 2056752 | E25: 2023722 | F25: 1915218 | G25: 10247457
A27: #VALUE! | D27: Region | E27: Sum of profit margin
D28: Aswan | E28: 17.508859
D29: Ismailia | E29: 17.930588
D30: Cairo | E30: 18.849936
D31: Giza | E31: 18.862696
D32: Alex | E32: 18.982332
D33: Mansoura | E33: 19.150365
D34: Zagazig | E34: 19.462071
D35: Marasa Matrouh | E35: 19.480625
D36: Minia | E36: 19.560263 | F36: Region | G36: Sum of Sales | H36: Sum of Profit
D37: Portsaied | E37: 20.347307 | F37: Smartphones | G37: 57308940 | H37: 3470868
D38: Grand Total | E38: 190.13504 | F38: iPhone 5S (16GB) | G38: 9978840 | H38: 602496
F39: iPhone 5S (32GB) | G39: 13186980 | H39: 821484
F40: iPhone 5S (64GB) | G40: 13724100 | H40: 835380
F41: Samsung Galaxy Note3 (32GB) - 3G | G41: 10224720 | H41: 604188
F42: Samsung Galaxy Note3 (32GB) - 4G | G42: 10194300 | H42: 607320
F43: Tablets | G43: 38558700 | H43: 2829276
F44: Microsoft Surface Pro 2 | G44: 18030600 | H44: 1322244
...

Sheet Dashboards
H6: Total of quantity | J6: Total of Sales
